Filename: /home/bryan/Desktop/Utilities/Python/RevPie/AutoRevPie/logs.txt


 - - - Logs (2019-06-06 10:44.48) - - - 


2019-06-06 10:45:40.565678 
-------------------- 

getRepsUpdate(): timeout exception

Message: 

Traceback (most recent call last):
  File "/home/bryan/Desktop/Utilities/Python/RevPie/AutoRevPie/AutomateRevPie/AutomateRevPie.py", line 695, in getStatsUpdate
    expected_conditions.alert_is_present())
  File "/home/bryan/anaconda3/envs/environment_2/lib/python3.7/site-packages/selenium/webdriver/support/wait.py", line 80, in until
    raise TimeoutException(message, screen, stacktrace)
selenium.common.exceptions.TimeoutException: Message: 


