Filename: /home/bryan/Desktop/Utilities/Python/RevPie/AutoRevPie/logs.txt


 - - - Logs (2019-06-06 10:59.45) - - - 


2019-06-06 11:00:37.527875 
-------------------- 

getRepsUpdate(): timeout exception

Message: 

Traceback (most recent call last):
  File "/home/bryan/Desktop/Utilities/Python/RevPie/AutoRevPie/AutomateRevPie/AutomateRevPie.py", line 695, in getStatsUpdate
    expected_conditions.alert_is_present())
  File "/home/bryan/anaconda3/envs/environment_2/lib/python3.7/site-packages/selenium/webdriver/support/wait.py", line 80, in until
    raise TimeoutException(message, screen, stacktrace)
selenium.common.exceptions.TimeoutException: Message: 


2019-06-06 11:01:07.802974 
-------------------- 

getStatsTable(): error while loading table, check logs

Message: 

Traceback (most recent call last):
  File "/home/bryan/Desktop/Utilities/Python/RevPie/AutoRevPie/AutomateRevPie/AutomateRevPie.py", line 643, in getStatsTable
    (By.XPATH, "//table[@class='table striped bordered hovered']")))
  File "/home/bryan/anaconda3/envs/environment_2/lib/python3.7/site-packages/selenium/webdriver/support/wait.py", line 80, in until
    raise TimeoutException(message, screen, stacktrace)
selenium.common.exceptions.TimeoutException: Message: 


2019-06-06 11:01:25.855352 
-------------------- 


Traceback (most recent call last):
  File "/home/bryan/Desktop/Utilities/Python/RevPie/AutoRevPie/AutomateRevPie/AutomateRevPie.py", line 736, in waiting
    time.sleep(duration)
KeyboardInterrupt

2019-06-06 11:01:25.857175 
-------------------- 

checkBrowser: Error, closing...

HTTPConnectionPool(host='127.0.0.1', port=49779): Max retries exceeded with url: /session/be5dd6cf-ad76-4fc8-b5a9-09176771fe7b/title (Caused by NewConnectionError('<urllib3.connection.HTTPConnection object at 0x7fd214a8f7b8>: Failed to establish a new connection: [Errno 111] Connection refused'))
Traceback (most recent call last):
  File "/home/bryan/Desktop/Utilities/Python/RevPie/AutoRevPie/AutomateRevPie/AutomateRevPie.py", line 736, in waiting
    time.sleep(duration)
KeyboardInterrupt

During handling of the above exception, another exception occurred:

Traceback (most recent call last):
  File "/home/bryan/anaconda3/envs/environment_2/lib/python3.7/site-packages/urllib3/connection.py", line 159, in _new_conn
    (self._dns_host, self.port), self.timeout, **extra_kw)
  File "/home/bryan/anaconda3/envs/environment_2/lib/python3.7/site-packages/urllib3/util/connection.py", line 80, in create_connection
    raise err
  File "/home/bryan/anaconda3/envs/environment_2/lib/python3.7/site-packages/urllib3/util/connection.py", line 70, in create_connection
    sock.connect(sa)
ConnectionRefusedError: [Errno 111] Connection refused

During handling of the above exception, another exception occurred:

Traceback (most recent call last):
  File "/home/bryan/anaconda3/envs/environment_2/lib/python3.7/site-packages/urllib3/connectionpool.py", line 600, in urlopen
    chunked=chunked)
  File "/home/bryan/anaconda3/envs/environment_2/lib/python3.7/site-packages/urllib3/connectionpool.py", line 354, in _make_request
    conn.request(method, url, **httplib_request_kw)
  File "/home/bryan/anaconda3/envs/environment_2/lib/python3.7/http/client.py", line 1229, in request
    self._send_request(method, url, body, headers, encode_chunked)
  File "/home/bryan/anaconda3/envs/environment_2/lib/python3.7/http/client.py", line 1275, in _send_request
    self.endheaders(body, encode_chunked=encode_chunked)
  File "/home/bryan/anaconda3/envs/environment_2/lib/python3.7/http/client.py", line 1224, in endheaders
    self._send_output(message_body, encode_chunked=encode_chunked)
  File "/home/bryan/anaconda3/envs/environment_2/lib/python3.7/http/client.py", line 1016, in _send_output
    self.send(msg)
  File "/home/bryan/anaconda3/envs/environment_2/lib/python3.7/http/client.py", line 956, in send
    self.connect()
  File "/home/bryan/anaconda3/envs/environment_2/lib/python3.7/site-packages/urllib3/connection.py", line 181, in connect
    conn = self._new_conn()
  File "/home/bryan/anaconda3/envs/environment_2/lib/python3.7/site-packages/urllib3/connection.py", line 168, in _new_conn
    self, "Failed to establish a new connection: %s" % e)
urllib3.exceptions.NewConnectionError: <urllib3.connection.HTTPConnection object at 0x7fd214a8f7b8>: Failed to establish a new connection: [Errno 111] Connection refused

During handling of the above exception, another exception occurred:

Traceback (most recent call last):
  File "/home/bryan/Desktop/Utilities/Python/RevPie/AutoRevPie/AutomateRevPie/AutomateRevPie.py", line 763, in checkBrowser
    browser.title
  File "/home/bryan/anaconda3/envs/environment_2/lib/python3.7/site-packages/selenium/webdriver/remote/webdriver.py", line 342, in title
    resp = self.execute(Command.GET_TITLE)
  File "/home/bryan/anaconda3/envs/environment_2/lib/python3.7/site-packages/selenium/webdriver/remote/webdriver.py", line 319, in execute
    response = self.command_executor.execute(driver_command, params)
  File "/home/bryan/anaconda3/envs/environment_2/lib/python3.7/site-packages/selenium/webdriver/remote/remote_connection.py", line 374, in execute
    return self._request(command_info[0], url, body=data)
  File "/home/bryan/anaconda3/envs/environment_2/lib/python3.7/site-packages/selenium/webdriver/remote/remote_connection.py", line 397, in _request
    resp = self._conn.request(method, url, body=body, headers=headers)
  File "/home/bryan/anaconda3/envs/environment_2/lib/python3.7/site-packages/urllib3/request.py", line 68, in request
    **urlopen_kw)
  File "/home/bryan/anaconda3/envs/environment_2/lib/python3.7/site-packages/urllib3/request.py", line 89, in request_encode_url
    return self.urlopen(method, url, **extra_kw)
  File "/home/bryan/anaconda3/envs/environment_2/lib/python3.7/site-packages/urllib3/poolmanager.py", line 324, in urlopen
    response = conn.urlopen(method, u.request_uri, **kw)
  File "/home/bryan/anaconda3/envs/environment_2/lib/python3.7/site-packages/urllib3/connectionpool.py", line 667, in urlopen
    **response_kw)
  File "/home/bryan/anaconda3/envs/environment_2/lib/python3.7/site-packages/urllib3/connectionpool.py", line 667, in urlopen
    **response_kw)
  File "/home/bryan/anaconda3/envs/environment_2/lib/python3.7/site-packages/urllib3/connectionpool.py", line 667, in urlopen
    **response_kw)
  File "/home/bryan/anaconda3/envs/environment_2/lib/python3.7/site-packages/urllib3/connectionpool.py", line 638, in urlopen
    _stacktrace=sys.exc_info()[2])
  File "/home/bryan/anaconda3/envs/environment_2/lib/python3.7/site-packages/urllib3/util/retry.py", line 399, in increment
    raise MaxRetryError(_pool, url, error or ResponseError(cause))
urllib3.exceptions.MaxRetryError: HTTPConnectionPool(host='127.0.0.1', port=49779): Max retries exceeded with url: /session/be5dd6cf-ad76-4fc8-b5a9-09176771fe7b/title (Caused by NewConnectionError('<urllib3.connection.HTTPConnection object at 0x7fd214a8f7b8>: Failed to establish a new connection: [Errno 111] Connection refused'))

2019-06-06 11:01:25.885554 
-------------------- 

Error: unable to update rep count...
HTTPConnectionPool(host='127.0.0.1', port=49779): Max retries exceeded with url: /session/be5dd6cf-ad76-4fc8-b5a9-09176771fe7b/element (Caused by NewConnectionError('<urllib3.connection.HTTPConnection object at 0x7fd214ab3630>: Failed to establish a new connection: [Errno 111] Connection refused'))
Traceback (most recent call last):
  File "/home/bryan/anaconda3/envs/environment_2/lib/python3.7/site-packages/urllib3/connection.py", line 159, in _new_conn
    (self._dns_host, self.port), self.timeout, **extra_kw)
  File "/home/bryan/anaconda3/envs/environment_2/lib/python3.7/site-packages/urllib3/util/connection.py", line 80, in create_connection
    raise err
  File "/home/bryan/anaconda3/envs/environment_2/lib/python3.7/site-packages/urllib3/util/connection.py", line 70, in create_connection
    sock.connect(sa)
ConnectionRefusedError: [Errno 111] Connection refused

During handling of the above exception, another exception occurred:

Traceback (most recent call last):
  File "/home/bryan/anaconda3/envs/environment_2/lib/python3.7/site-packages/urllib3/connectionpool.py", line 600, in urlopen
    chunked=chunked)
  File "/home/bryan/anaconda3/envs/environment_2/lib/python3.7/site-packages/urllib3/connectionpool.py", line 354, in _make_request
    conn.request(method, url, **httplib_request_kw)
  File "/home/bryan/anaconda3/envs/environment_2/lib/python3.7/http/client.py", line 1229, in request
    self._send_request(method, url, body, headers, encode_chunked)
  File "/home/bryan/anaconda3/envs/environment_2/lib/python3.7/http/client.py", line 1275, in _send_request
    self.endheaders(body, encode_chunked=encode_chunked)
  File "/home/bryan/anaconda3/envs/environment_2/lib/python3.7/http/client.py", line 1224, in endheaders
    self._send_output(message_body, encode_chunked=encode_chunked)
  File "/home/bryan/anaconda3/envs/environment_2/lib/python3.7/http/client.py", line 1016, in _send_output
    self.send(msg)
  File "/home/bryan/anaconda3/envs/environment_2/lib/python3.7/http/client.py", line 956, in send
    self.connect()
  File "/home/bryan/anaconda3/envs/environment_2/lib/python3.7/site-packages/urllib3/connection.py", line 181, in connect
    conn = self._new_conn()
  File "/home/bryan/anaconda3/envs/environment_2/lib/python3.7/site-packages/urllib3/connection.py", line 168, in _new_conn
    self, "Failed to establish a new connection: %s" % e)
urllib3.exceptions.NewConnectionError: <urllib3.connection.HTTPConnection object at 0x7fd214ab3630>: Failed to establish a new connection: [Errno 111] Connection refused

During handling of the above exception, another exception occurred:

Traceback (most recent call last):
  File "AutoRevPie.py", line 142, in <module>
    AutoRP_obj.autoRevPie(RepCounter.repCount)
  File "/home/bryan/Desktop/Utilities/Python/RevPie/AutoRevPie/AutomateRevPie/AutomateRevPie.py", line 335, in autoRevPie
    , self.campaigns[self.currentCampaign+1][0])
  File "/home/bryan/Desktop/Utilities/Python/RevPie/AutoRevPie/AutomateRevPie/AutomateRevPie.py", line 170, in switchCampaigns
    BidAdjuster.changeBids(*Bids, _option='-p')
  File "/home/bryan/Desktop/Utilities/Python/RevPie/AutoRevPie/AutomateRevPie/AutomateRevPie.py", line 486, in changeBids
    'bidAdjustmentsDateFilter').get_attribute(
  File "/home/bryan/anaconda3/envs/environment_2/lib/python3.7/site-packages/selenium/webdriver/remote/webdriver.py", line 360, in find_element_by_id
    return self.find_element(by=By.ID, value=id_)
  File "/home/bryan/anaconda3/envs/environment_2/lib/python3.7/site-packages/selenium/webdriver/remote/webdriver.py", line 978, in find_element
    'value': value})['value']
  File "/home/bryan/anaconda3/envs/environment_2/lib/python3.7/site-packages/selenium/webdriver/remote/webdriver.py", line 319, in execute
    response = self.command_executor.execute(driver_command, params)
  File "/home/bryan/anaconda3/envs/environment_2/lib/python3.7/site-packages/selenium/webdriver/remote/remote_connection.py", line 374, in execute
    return self._request(command_info[0], url, body=data)
  File "/home/bryan/anaconda3/envs/environment_2/lib/python3.7/site-packages/selenium/webdriver/remote/remote_connection.py", line 397, in _request
    resp = self._conn.request(method, url, body=body, headers=headers)
  File "/home/bryan/anaconda3/envs/environment_2/lib/python3.7/site-packages/urllib3/request.py", line 72, in request
    **urlopen_kw)
  File "/home/bryan/anaconda3/envs/environment_2/lib/python3.7/site-packages/urllib3/request.py", line 150, in request_encode_body
    return self.urlopen(method, url, **extra_kw)
  File "/home/bryan/anaconda3/envs/environment_2/lib/python3.7/site-packages/urllib3/poolmanager.py", line 324, in urlopen
    response = conn.urlopen(method, u.request_uri, **kw)
  File "/home/bryan/anaconda3/envs/environment_2/lib/python3.7/site-packages/urllib3/connectionpool.py", line 667, in urlopen
    **response_kw)
  File "/home/bryan/anaconda3/envs/environment_2/lib/python3.7/site-packages/urllib3/connectionpool.py", line 667, in urlopen
    **response_kw)
  File "/home/bryan/anaconda3/envs/environment_2/lib/python3.7/site-packages/urllib3/connectionpool.py", line 667, in urlopen
    **response_kw)
  File "/home/bryan/anaconda3/envs/environment_2/lib/python3.7/site-packages/urllib3/connectionpool.py", line 638, in urlopen
    _stacktrace=sys.exc_info()[2])
  File "/home/bryan/anaconda3/envs/environment_2/lib/python3.7/site-packages/urllib3/util/retry.py", line 399, in increment
    raise MaxRetryError(_pool, url, error or ResponseError(cause))
urllib3.exceptions.MaxRetryError: HTTPConnectionPool(host='127.0.0.1', port=49779): Max retries exceeded with url: /session/be5dd6cf-ad76-4fc8-b5a9-09176771fe7b/element (Caused by NewConnectionError('<urllib3.connection.HTTPConnection object at 0x7fd214ab3630>: Failed to establish a new connection: [Errno 111] Connection refused'))

2019-06-06 11:01:25.889597 
-------------------- 

checkBrowser: Error, closing...

HTTPConnectionPool(host='127.0.0.1', port=49779): Max retries exceeded with url: /session/be5dd6cf-ad76-4fc8-b5a9-09176771fe7b/title (Caused by NewConnectionError('<urllib3.connection.HTTPConnection object at 0x7fd214c0b198>: Failed to establish a new connection: [Errno 111] Connection refused'))
Traceback (most recent call last):
  File "/home/bryan/anaconda3/envs/environment_2/lib/python3.7/site-packages/urllib3/connection.py", line 159, in _new_conn
    (self._dns_host, self.port), self.timeout, **extra_kw)
  File "/home/bryan/anaconda3/envs/environment_2/lib/python3.7/site-packages/urllib3/util/connection.py", line 80, in create_connection
    raise err
  File "/home/bryan/anaconda3/envs/environment_2/lib/python3.7/site-packages/urllib3/util/connection.py", line 70, in create_connection
    sock.connect(sa)
ConnectionRefusedError: [Errno 111] Connection refused

During handling of the above exception, another exception occurred:

Traceback (most recent call last):
  File "/home/bryan/anaconda3/envs/environment_2/lib/python3.7/site-packages/urllib3/connectionpool.py", line 600, in urlopen
    chunked=chunked)
  File "/home/bryan/anaconda3/envs/environment_2/lib/python3.7/site-packages/urllib3/connectionpool.py", line 354, in _make_request
    conn.request(method, url, **httplib_request_kw)
  File "/home/bryan/anaconda3/envs/environment_2/lib/python3.7/http/client.py", line 1229, in request
    self._send_request(method, url, body, headers, encode_chunked)
  File "/home/bryan/anaconda3/envs/environment_2/lib/python3.7/http/client.py", line 1275, in _send_request
    self.endheaders(body, encode_chunked=encode_chunked)
  File "/home/bryan/anaconda3/envs/environment_2/lib/python3.7/http/client.py", line 1224, in endheaders
    self._send_output(message_body, encode_chunked=encode_chunked)
  File "/home/bryan/anaconda3/envs/environment_2/lib/python3.7/http/client.py", line 1016, in _send_output
    self.send(msg)
  File "/home/bryan/anaconda3/envs/environment_2/lib/python3.7/http/client.py", line 956, in send
    self.connect()
  File "/home/bryan/anaconda3/envs/environment_2/lib/python3.7/site-packages/urllib3/connection.py", line 181, in connect
    conn = self._new_conn()
  File "/home/bryan/anaconda3/envs/environment_2/lib/python3.7/site-packages/urllib3/connection.py", line 168, in _new_conn
    self, "Failed to establish a new connection: %s" % e)
urllib3.exceptions.NewConnectionError: <urllib3.connection.HTTPConnection object at 0x7fd214c0b198>: Failed to establish a new connection: [Errno 111] Connection refused

During handling of the above exception, another exception occurred:

Traceback (most recent call last):
  File "/home/bryan/Desktop/Utilities/Python/RevPie/AutoRevPie/AutomateRevPie/AutomateRevPie.py", line 763, in checkBrowser
    browser.title
  File "/home/bryan/anaconda3/envs/environment_2/lib/python3.7/site-packages/selenium/webdriver/remote/webdriver.py", line 342, in title
    resp = self.execute(Command.GET_TITLE)
  File "/home/bryan/anaconda3/envs/environment_2/lib/python3.7/site-packages/selenium/webdriver/remote/webdriver.py", line 319, in execute
    response = self.command_executor.execute(driver_command, params)
  File "/home/bryan/anaconda3/envs/environment_2/lib/python3.7/site-packages/selenium/webdriver/remote/remote_connection.py", line 374, in execute
    return self._request(command_info[0], url, body=data)
  File "/home/bryan/anaconda3/envs/environment_2/lib/python3.7/site-packages/selenium/webdriver/remote/remote_connection.py", line 397, in _request
    resp = self._conn.request(method, url, body=body, headers=headers)
  File "/home/bryan/anaconda3/envs/environment_2/lib/python3.7/site-packages/urllib3/request.py", line 68, in request
    **urlopen_kw)
  File "/home/bryan/anaconda3/envs/environment_2/lib/python3.7/site-packages/urllib3/request.py", line 89, in request_encode_url
    return self.urlopen(method, url, **extra_kw)
  File "/home/bryan/anaconda3/envs/environment_2/lib/python3.7/site-packages/urllib3/poolmanager.py", line 324, in urlopen
    response = conn.urlopen(method, u.request_uri, **kw)
  File "/home/bryan/anaconda3/envs/environment_2/lib/python3.7/site-packages/urllib3/connectionpool.py", line 667, in urlopen
    **response_kw)
  File "/home/bryan/anaconda3/envs/environment_2/lib/python3.7/site-packages/urllib3/connectionpool.py", line 667, in urlopen
    **response_kw)
  File "/home/bryan/anaconda3/envs/environment_2/lib/python3.7/site-packages/urllib3/connectionpool.py", line 667, in urlopen
    **response_kw)
  File "/home/bryan/anaconda3/envs/environment_2/lib/python3.7/site-packages/urllib3/connectionpool.py", line 638, in urlopen
    _stacktrace=sys.exc_info()[2])
  File "/home/bryan/anaconda3/envs/environment_2/lib/python3.7/site-packages/urllib3/util/retry.py", line 399, in increment
    raise MaxRetryError(_pool, url, error or ResponseError(cause))
urllib3.exceptions.MaxRetryError: HTTPConnectionPool(host='127.0.0.1', port=49779): Max retries exceeded with url: /session/be5dd6cf-ad76-4fc8-b5a9-09176771fe7b/title (Caused by NewConnectionError('<urllib3.connection.HTTPConnection object at 0x7fd214c0b198>: Failed to establish a new connection: [Errno 111] Connection refused'))

2019-06-06 11:01:25.892314 
-------------------- 

checkBrowser: Error, closing...

HTTPConnectionPool(host='127.0.0.1', port=49779): Max retries exceeded with url: /session/be5dd6cf-ad76-4fc8-b5a9-09176771fe7b/title (Caused by NewConnectionError('<urllib3.connection.HTTPConnection object at 0x7fd214a8f748>: Failed to establish a new connection: [Errno 111] Connection refused'))
Traceback (most recent call last):
  File "/home/bryan/anaconda3/envs/environment_2/lib/python3.7/site-packages/urllib3/connection.py", line 159, in _new_conn
    (self._dns_host, self.port), self.timeout, **extra_kw)
  File "/home/bryan/anaconda3/envs/environment_2/lib/python3.7/site-packages/urllib3/util/connection.py", line 80, in create_connection
    raise err
  File "/home/bryan/anaconda3/envs/environment_2/lib/python3.7/site-packages/urllib3/util/connection.py", line 70, in create_connection
    sock.connect(sa)
ConnectionRefusedError: [Errno 111] Connection refused

During handling of the above exception, another exception occurred:

Traceback (most recent call last):
  File "/home/bryan/anaconda3/envs/environment_2/lib/python3.7/site-packages/urllib3/connectionpool.py", line 600, in urlopen
    chunked=chunked)
  File "/home/bryan/anaconda3/envs/environment_2/lib/python3.7/site-packages/urllib3/connectionpool.py", line 354, in _make_request
    conn.request(method, url, **httplib_request_kw)
  File "/home/bryan/anaconda3/envs/environment_2/lib/python3.7/http/client.py", line 1229, in request
    self._send_request(method, url, body, headers, encode_chunked)
  File "/home/bryan/anaconda3/envs/environment_2/lib/python3.7/http/client.py", line 1275, in _send_request
    self.endheaders(body, encode_chunked=encode_chunked)
  File "/home/bryan/anaconda3/envs/environment_2/lib/python3.7/http/client.py", line 1224, in endheaders
    self._send_output(message_body, encode_chunked=encode_chunked)
  File "/home/bryan/anaconda3/envs/environment_2/lib/python3.7/http/client.py", line 1016, in _send_output
    self.send(msg)
  File "/home/bryan/anaconda3/envs/environment_2/lib/python3.7/http/client.py", line 956, in send
    self.connect()
  File "/home/bryan/anaconda3/envs/environment_2/lib/python3.7/site-packages/urllib3/connection.py", line 181, in connect
    conn = self._new_conn()
  File "/home/bryan/anaconda3/envs/environment_2/lib/python3.7/site-packages/urllib3/connection.py", line 168, in _new_conn
    self, "Failed to establish a new connection: %s" % e)
urllib3.exceptions.NewConnectionError: <urllib3.connection.HTTPConnection object at 0x7fd214a8f748>: Failed to establish a new connection: [Errno 111] Connection refused

During handling of the above exception, another exception occurred:

Traceback (most recent call last):
  File "/home/bryan/Desktop/Utilities/Python/RevPie/AutoRevPie/AutomateRevPie/AutomateRevPie.py", line 763, in checkBrowser
    browser.title
  File "/home/bryan/anaconda3/envs/environment_2/lib/python3.7/site-packages/selenium/webdriver/remote/webdriver.py", line 342, in title
    resp = self.execute(Command.GET_TITLE)
  File "/home/bryan/anaconda3/envs/environment_2/lib/python3.7/site-packages/selenium/webdriver/remote/webdriver.py", line 319, in execute
    response = self.command_executor.execute(driver_command, params)
  File "/home/bryan/anaconda3/envs/environment_2/lib/python3.7/site-packages/selenium/webdriver/remote/remote_connection.py", line 374, in execute
    return self._request(command_info[0], url, body=data)
  File "/home/bryan/anaconda3/envs/environment_2/lib/python3.7/site-packages/selenium/webdriver/remote/remote_connection.py", line 397, in _request
    resp = self._conn.request(method, url, body=body, headers=headers)
  File "/home/bryan/anaconda3/envs/environment_2/lib/python3.7/site-packages/urllib3/request.py", line 68, in request
    **urlopen_kw)
  File "/home/bryan/anaconda3/envs/environment_2/lib/python3.7/site-packages/urllib3/request.py", line 89, in request_encode_url
    return self.urlopen(method, url, **extra_kw)
  File "/home/bryan/anaconda3/envs/environment_2/lib/python3.7/site-packages/urllib3/poolmanager.py", line 324, in urlopen
    response = conn.urlopen(method, u.request_uri, **kw)
  File "/home/bryan/anaconda3/envs/environment_2/lib/python3.7/site-packages/urllib3/connectionpool.py", line 667, in urlopen
    **response_kw)
  File "/home/bryan/anaconda3/envs/environment_2/lib/python3.7/site-packages/urllib3/connectionpool.py", line 667, in urlopen
    **response_kw)
  File "/home/bryan/anaconda3/envs/environment_2/lib/python3.7/site-packages/urllib3/connectionpool.py", line 667, in urlopen
    **response_kw)
  File "/home/bryan/anaconda3/envs/environment_2/lib/python3.7/site-packages/urllib3/connectionpool.py", line 638, in urlopen
    _stacktrace=sys.exc_info()[2])
  File "/home/bryan/anaconda3/envs/environment_2/lib/python3.7/site-packages/urllib3/util/retry.py", line 399, in increment
    raise MaxRetryError(_pool, url, error or ResponseError(cause))
urllib3.exceptions.MaxRetryError: HTTPConnectionPool(host='127.0.0.1', port=49779): Max retries exceeded with url: /session/be5dd6cf-ad76-4fc8-b5a9-09176771fe7b/title (Caused by NewConnectionError('<urllib3.connection.HTTPConnection object at 0x7fd214a8f748>: Failed to establish a new connection: [Errno 111] Connection refused'))

2019-06-06 11:01:26.895089 
-------------------- 


switchTabs: Error while switching tabs, closing...

HTTPConnectionPool(host='127.0.0.1', port=49779): Max retries exceeded with url: /session/be5dd6cf-ad76-4fc8-b5a9-09176771fe7b/window/handles (Caused by NewConnectionError('<urllib3.connection.HTTPConnection object at 0x7fd214ab3ba8>: Failed to establish a new connection: [Errno 111] Connection refused'))
Traceback (most recent call last):
  File "/home/bryan/anaconda3/envs/environment_2/lib/python3.7/site-packages/urllib3/connection.py", line 159, in _new_conn
    (self._dns_host, self.port), self.timeout, **extra_kw)
  File "/home/bryan/anaconda3/envs/environment_2/lib/python3.7/site-packages/urllib3/util/connection.py", line 80, in create_connection
    raise err
  File "/home/bryan/anaconda3/envs/environment_2/lib/python3.7/site-packages/urllib3/util/connection.py", line 70, in create_connection
    sock.connect(sa)
ConnectionRefusedError: [Errno 111] Connection refused

During handling of the above exception, another exception occurred:

Traceback (most recent call last):
  File "/home/bryan/anaconda3/envs/environment_2/lib/python3.7/site-packages/urllib3/connectionpool.py", line 600, in urlopen
    chunked=chunked)
  File "/home/bryan/anaconda3/envs/environment_2/lib/python3.7/site-packages/urllib3/connectionpool.py", line 354, in _make_request
    conn.request(method, url, **httplib_request_kw)
  File "/home/bryan/anaconda3/envs/environment_2/lib/python3.7/http/client.py", line 1229, in request
    self._send_request(method, url, body, headers, encode_chunked)
  File "/home/bryan/anaconda3/envs/environment_2/lib/python3.7/http/client.py", line 1275, in _send_request
    self.endheaders(body, encode_chunked=encode_chunked)
  File "/home/bryan/anaconda3/envs/environment_2/lib/python3.7/http/client.py", line 1224, in endheaders
    self._send_output(message_body, encode_chunked=encode_chunked)
  File "/home/bryan/anaconda3/envs/environment_2/lib/python3.7/http/client.py", line 1016, in _send_output
    self.send(msg)
  File "/home/bryan/anaconda3/envs/environment_2/lib/python3.7/http/client.py", line 956, in send
    self.connect()
  File "/home/bryan/anaconda3/envs/environment_2/lib/python3.7/site-packages/urllib3/connection.py", line 181, in connect
    conn = self._new_conn()
  File "/home/bryan/anaconda3/envs/environment_2/lib/python3.7/site-packages/urllib3/connection.py", line 168, in _new_conn
    self, "Failed to establish a new connection: %s" % e)
urllib3.exceptions.NewConnectionError: <urllib3.connection.HTTPConnection object at 0x7fd214ab3ba8>: Failed to establish a new connection: [Errno 111] Connection refused

During handling of the above exception, another exception occurred:

Traceback (most recent call last):
  File "/home/bryan/Desktop/Utilities/Python/RevPie/AutoRevPie/AutomateRevPie/AutomateRevPie.py", line 749, in switchToTab
    browser.switch_to.window(browser.window_handles[tab])
  File "/home/bryan/anaconda3/envs/environment_2/lib/python3.7/site-packages/selenium/webdriver/remote/webdriver.py", line 724, in window_handles
    return self.execute(Command.W3C_GET_WINDOW_HANDLES)['value']
  File "/home/bryan/anaconda3/envs/environment_2/lib/python3.7/site-packages/selenium/webdriver/remote/webdriver.py", line 319, in execute
    response = self.command_executor.execute(driver_command, params)
  File "/home/bryan/anaconda3/envs/environment_2/lib/python3.7/site-packages/selenium/webdriver/remote/remote_connection.py", line 374, in execute
    return self._request(command_info[0], url, body=data)
  File "/home/bryan/anaconda3/envs/environment_2/lib/python3.7/site-packages/selenium/webdriver/remote/remote_connection.py", line 397, in _request
    resp = self._conn.request(method, url, body=body, headers=headers)
  File "/home/bryan/anaconda3/envs/environment_2/lib/python3.7/site-packages/urllib3/request.py", line 68, in request
    **urlopen_kw)
  File "/home/bryan/anaconda3/envs/environment_2/lib/python3.7/site-packages/urllib3/request.py", line 89, in request_encode_url
    return self.urlopen(method, url, **extra_kw)
  File "/home/bryan/anaconda3/envs/environment_2/lib/python3.7/site-packages/urllib3/poolmanager.py", line 324, in urlopen
    response = conn.urlopen(method, u.request_uri, **kw)
  File "/home/bryan/anaconda3/envs/environment_2/lib/python3.7/site-packages/urllib3/connectionpool.py", line 667, in urlopen
    **response_kw)
  File "/home/bryan/anaconda3/envs/environment_2/lib/python3.7/site-packages/urllib3/connectionpool.py", line 667, in urlopen
    **response_kw)
  File "/home/bryan/anaconda3/envs/environment_2/lib/python3.7/site-packages/urllib3/connectionpool.py", line 667, in urlopen
    **response_kw)
  File "/home/bryan/anaconda3/envs/environment_2/lib/python3.7/site-packages/urllib3/connectionpool.py", line 638, in urlopen
    _stacktrace=sys.exc_info()[2])
  File "/home/bryan/anaconda3/envs/environment_2/lib/python3.7/site-packages/urllib3/util/retry.py", line 399, in increment
    raise MaxRetryError(_pool, url, error or ResponseError(cause))
urllib3.exceptions.MaxRetryError: HTTPConnectionPool(host='127.0.0.1', port=49779): Max retries exceeded with url: /session/be5dd6cf-ad76-4fc8-b5a9-09176771fe7b/window/handles (Caused by NewConnectionError('<urllib3.connection.HTTPConnection object at 0x7fd214ab3ba8>: Failed to establish a new connection: [Errno 111] Connection refused'))

2019-06-06 11:01:26.897273 
-------------------- 

Browser error: wallboard

HTTPConnectionPool(host='127.0.0.1', port=49779): Max retries exceeded with url: /session/be5dd6cf-ad76-4fc8-b5a9-09176771fe7b/element (Caused by NewConnectionError('<urllib3.connection.HTTPConnection object at 0x7fd214a62160>: Failed to establish a new connection: [Errno 111] Connection refused'))
Traceback (most recent call last):
  File "/home/bryan/anaconda3/envs/environment_2/lib/python3.7/site-packages/urllib3/connection.py", line 159, in _new_conn
    (self._dns_host, self.port), self.timeout, **extra_kw)
  File "/home/bryan/anaconda3/envs/environment_2/lib/python3.7/site-packages/urllib3/util/connection.py", line 80, in create_connection
    raise err
  File "/home/bryan/anaconda3/envs/environment_2/lib/python3.7/site-packages/urllib3/util/connection.py", line 70, in create_connection
    sock.connect(sa)
ConnectionRefusedError: [Errno 111] Connection refused

During handling of the above exception, another exception occurred:

Traceback (most recent call last):
  File "/home/bryan/anaconda3/envs/environment_2/lib/python3.7/site-packages/urllib3/connectionpool.py", line 600, in urlopen
    chunked=chunked)
  File "/home/bryan/anaconda3/envs/environment_2/lib/python3.7/site-packages/urllib3/connectionpool.py", line 354, in _make_request
    conn.request(method, url, **httplib_request_kw)
  File "/home/bryan/anaconda3/envs/environment_2/lib/python3.7/http/client.py", line 1229, in request
    self._send_request(method, url, body, headers, encode_chunked)
  File "/home/bryan/anaconda3/envs/environment_2/lib/python3.7/http/client.py", line 1275, in _send_request
    self.endheaders(body, encode_chunked=encode_chunked)
  File "/home/bryan/anaconda3/envs/environment_2/lib/python3.7/http/client.py", line 1224, in endheaders
    self._send_output(message_body, encode_chunked=encode_chunked)
  File "/home/bryan/anaconda3/envs/environment_2/lib/python3.7/http/client.py", line 1016, in _send_output
    self.send(msg)
  File "/home/bryan/anaconda3/envs/environment_2/lib/python3.7/http/client.py", line 956, in send
    self.connect()
  File "/home/bryan/anaconda3/envs/environment_2/lib/python3.7/site-packages/urllib3/connection.py", line 181, in connect
    conn = self._new_conn()
  File "/home/bryan/anaconda3/envs/environment_2/lib/python3.7/site-packages/urllib3/connection.py", line 168, in _new_conn
    self, "Failed to establish a new connection: %s" % e)
urllib3.exceptions.NewConnectionError: <urllib3.connection.HTTPConnection object at 0x7fd214a62160>: Failed to establish a new connection: [Errno 111] Connection refused

During handling of the above exception, another exception occurred:

Traceback (most recent call last):
  File "/home/bryan/Desktop/Utilities/Python/RevPie/AutoRevPie/AutomateRevPie/AutomateRevPie.py", line 242, in getCalls
    (By.CLASS_NAME, 'container')))
  File "/home/bryan/anaconda3/envs/environment_2/lib/python3.7/site-packages/selenium/webdriver/support/wait.py", line 71, in until
    value = method(self._driver)
  File "/home/bryan/anaconda3/envs/environment_2/lib/python3.7/site-packages/selenium/webdriver/support/expected_conditions.py", line 64, in __call__
    return _find_element(driver, self.locator)
  File "/home/bryan/anaconda3/envs/environment_2/lib/python3.7/site-packages/selenium/webdriver/support/expected_conditions.py", line 411, in _find_element
    return driver.find_element(*by)
  File "/home/bryan/anaconda3/envs/environment_2/lib/python3.7/site-packages/selenium/webdriver/remote/webdriver.py", line 978, in find_element
    'value': value})['value']
  File "/home/bryan/anaconda3/envs/environment_2/lib/python3.7/site-packages/selenium/webdriver/remote/webdriver.py", line 319, in execute
    response = self.command_executor.execute(driver_command, params)
  File "/home/bryan/anaconda3/envs/environment_2/lib/python3.7/site-packages/selenium/webdriver/remote/remote_connection.py", line 374, in execute
    return self._request(command_info[0], url, body=data)
  File "/home/bryan/anaconda3/envs/environment_2/lib/python3.7/site-packages/selenium/webdriver/remote/remote_connection.py", line 397, in _request
    resp = self._conn.request(method, url, body=body, headers=headers)
  File "/home/bryan/anaconda3/envs/environment_2/lib/python3.7/site-packages/urllib3/request.py", line 72, in request
    **urlopen_kw)
  File "/home/bryan/anaconda3/envs/environment_2/lib/python3.7/site-packages/urllib3/request.py", line 150, in request_encode_body
    return self.urlopen(method, url, **extra_kw)
  File "/home/bryan/anaconda3/envs/environment_2/lib/python3.7/site-packages/urllib3/poolmanager.py", line 324, in urlopen
    response = conn.urlopen(method, u.request_uri, **kw)
  File "/home/bryan/anaconda3/envs/environment_2/lib/python3.7/site-packages/urllib3/connectionpool.py", line 667, in urlopen
    **response_kw)
  File "/home/bryan/anaconda3/envs/environment_2/lib/python3.7/site-packages/urllib3/connectionpool.py", line 667, in urlopen
    **response_kw)
  File "/home/bryan/anaconda3/envs/environment_2/lib/python3.7/site-packages/urllib3/connectionpool.py", line 667, in urlopen
    **response_kw)
  File "/home/bryan/anaconda3/envs/environment_2/lib/python3.7/site-packages/urllib3/connectionpool.py", line 638, in urlopen
    _stacktrace=sys.exc_info()[2])
  File "/home/bryan/anaconda3/envs/environment_2/lib/python3.7/site-packages/urllib3/util/retry.py", line 399, in increment
    raise MaxRetryError(_pool, url, error or ResponseError(cause))
urllib3.exceptions.MaxRetryError: HTTPConnectionPool(host='127.0.0.1', port=49779): Max retries exceeded with url: /session/be5dd6cf-ad76-4fc8-b5a9-09176771fe7b/element (Caused by NewConnectionError('<urllib3.connection.HTTPConnection object at 0x7fd214a62160>: Failed to establish a new connection: [Errno 111] Connection refused'))

2019-06-06 11:01:26.899957 
-------------------- 

checkBrowser: Error, closing...

HTTPConnectionPool(host='127.0.0.1', port=49779): Max retries exceeded with url: /session/be5dd6cf-ad76-4fc8-b5a9-09176771fe7b/title (Caused by NewConnectionError('<urllib3.connection.HTTPConnection object at 0x7fd214a62710>: Failed to establish a new connection: [Errno 111] Connection refused'))
Traceback (most recent call last):
  File "/home/bryan/anaconda3/envs/environment_2/lib/python3.7/site-packages/urllib3/connection.py", line 159, in _new_conn
    (self._dns_host, self.port), self.timeout, **extra_kw)
  File "/home/bryan/anaconda3/envs/environment_2/lib/python3.7/site-packages/urllib3/util/connection.py", line 80, in create_connection
    raise err
  File "/home/bryan/anaconda3/envs/environment_2/lib/python3.7/site-packages/urllib3/util/connection.py", line 70, in create_connection
    sock.connect(sa)
ConnectionRefusedError: [Errno 111] Connection refused

During handling of the above exception, another exception occurred:

Traceback (most recent call last):
  File "/home/bryan/anaconda3/envs/environment_2/lib/python3.7/site-packages/urllib3/connectionpool.py", line 600, in urlopen
    chunked=chunked)
  File "/home/bryan/anaconda3/envs/environment_2/lib/python3.7/site-packages/urllib3/connectionpool.py", line 354, in _make_request
    conn.request(method, url, **httplib_request_kw)
  File "/home/bryan/anaconda3/envs/environment_2/lib/python3.7/http/client.py", line 1229, in request
    self._send_request(method, url, body, headers, encode_chunked)
  File "/home/bryan/anaconda3/envs/environment_2/lib/python3.7/http/client.py", line 1275, in _send_request
    self.endheaders(body, encode_chunked=encode_chunked)
  File "/home/bryan/anaconda3/envs/environment_2/lib/python3.7/http/client.py", line 1224, in endheaders
    self._send_output(message_body, encode_chunked=encode_chunked)
  File "/home/bryan/anaconda3/envs/environment_2/lib/python3.7/http/client.py", line 1016, in _send_output
    self.send(msg)
  File "/home/bryan/anaconda3/envs/environment_2/lib/python3.7/http/client.py", line 956, in send
    self.connect()
  File "/home/bryan/anaconda3/envs/environment_2/lib/python3.7/site-packages/urllib3/connection.py", line 181, in connect
    conn = self._new_conn()
  File "/home/bryan/anaconda3/envs/environment_2/lib/python3.7/site-packages/urllib3/connection.py", line 168, in _new_conn
    self, "Failed to establish a new connection: %s" % e)
urllib3.exceptions.NewConnectionError: <urllib3.connection.HTTPConnection object at 0x7fd214a62160>: Failed to establish a new connection: [Errno 111] Connection refused

During handling of the above exception, another exception occurred:

Traceback (most recent call last):
  File "/home/bryan/Desktop/Utilities/Python/RevPie/AutoRevPie/AutomateRevPie/AutomateRevPie.py", line 242, in getCalls
    (By.CLASS_NAME, 'container')))
  File "/home/bryan/anaconda3/envs/environment_2/lib/python3.7/site-packages/selenium/webdriver/support/wait.py", line 71, in until
    value = method(self._driver)
  File "/home/bryan/anaconda3/envs/environment_2/lib/python3.7/site-packages/selenium/webdriver/support/expected_conditions.py", line 64, in __call__
    return _find_element(driver, self.locator)
  File "/home/bryan/anaconda3/envs/environment_2/lib/python3.7/site-packages/selenium/webdriver/support/expected_conditions.py", line 411, in _find_element
    return driver.find_element(*by)
  File "/home/bryan/anaconda3/envs/environment_2/lib/python3.7/site-packages/selenium/webdriver/remote/webdriver.py", line 978, in find_element
    'value': value})['value']
  File "/home/bryan/anaconda3/envs/environment_2/lib/python3.7/site-packages/selenium/webdriver/remote/webdriver.py", line 319, in execute
    response = self.command_executor.execute(driver_command, params)
  File "/home/bryan/anaconda3/envs/environment_2/lib/python3.7/site-packages/selenium/webdriver/remote/remote_connection.py", line 374, in execute
    return self._request(command_info[0], url, body=data)
  File "/home/bryan/anaconda3/envs/environment_2/lib/python3.7/site-packages/selenium/webdriver/remote/remote_connection.py", line 397, in _request
    resp = self._conn.request(method, url, body=body, headers=headers)
  File "/home/bryan/anaconda3/envs/environment_2/lib/python3.7/site-packages/urllib3/request.py", line 72, in request
    **urlopen_kw)
  File "/home/bryan/anaconda3/envs/environment_2/lib/python3.7/site-packages/urllib3/request.py", line 150, in request_encode_body
    return self.urlopen(method, url, **extra_kw)
  File "/home/bryan/anaconda3/envs/environment_2/lib/python3.7/site-packages/urllib3/poolmanager.py", line 324, in urlopen
    response = conn.urlopen(method, u.request_uri, **kw)
  File "/home/bryan/anaconda3/envs/environment_2/lib/python3.7/site-packages/urllib3/connectionpool.py", line 667, in urlopen
    **response_kw)
  File "/home/bryan/anaconda3/envs/environment_2/lib/python3.7/site-packages/urllib3/connectionpool.py", line 667, in urlopen
    **response_kw)
  File "/home/bryan/anaconda3/envs/environment_2/lib/python3.7/site-packages/urllib3/connectionpool.py", line 667, in urlopen
    **response_kw)
  File "/home/bryan/anaconda3/envs/environment_2/lib/python3.7/site-packages/urllib3/connectionpool.py", line 638, in urlopen
    _stacktrace=sys.exc_info()[2])
  File "/home/bryan/anaconda3/envs/environment_2/lib/python3.7/site-packages/urllib3/util/retry.py", line 399, in increment
    raise MaxRetryError(_pool, url, error or ResponseError(cause))
urllib3.exceptions.MaxRetryError: HTTPConnectionPool(host='127.0.0.1', port=49779): Max retries exceeded with url: /session/be5dd6cf-ad76-4fc8-b5a9-09176771fe7b/element (Caused by NewConnectionError('<urllib3.connection.HTTPConnection object at 0x7fd214a62160>: Failed to establish a new connection: [Errno 111] Connection refused'))

During handling of the above exception, another exception occurred:

Traceback (most recent call last):
  File "/home/bryan/anaconda3/envs/environment_2/lib/python3.7/site-packages/urllib3/connection.py", line 159, in _new_conn
    (self._dns_host, self.port), self.timeout, **extra_kw)
  File "/home/bryan/anaconda3/envs/environment_2/lib/python3.7/site-packages/urllib3/util/connection.py", line 80, in create_connection
    raise err
  File "/home/bryan/anaconda3/envs/environment_2/lib/python3.7/site-packages/urllib3/util/connection.py", line 70, in create_connection
    sock.connect(sa)
ConnectionRefusedError: [Errno 111] Connection refused

During handling of the above exception, another exception occurred:

Traceback (most recent call last):
  File "/home/bryan/anaconda3/envs/environment_2/lib/python3.7/site-packages/urllib3/connectionpool.py", line 600, in urlopen
    chunked=chunked)
  File "/home/bryan/anaconda3/envs/environment_2/lib/python3.7/site-packages/urllib3/connectionpool.py", line 354, in _make_request
    conn.request(method, url, **httplib_request_kw)
  File "/home/bryan/anaconda3/envs/environment_2/lib/python3.7/http/client.py", line 1229, in request
    self._send_request(method, url, body, headers, encode_chunked)
  File "/home/bryan/anaconda3/envs/environment_2/lib/python3.7/http/client.py", line 1275, in _send_request
    self.endheaders(body, encode_chunked=encode_chunked)
  File "/home/bryan/anaconda3/envs/environment_2/lib/python3.7/http/client.py", line 1224, in endheaders
    self._send_output(message_body, encode_chunked=encode_chunked)
  File "/home/bryan/anaconda3/envs/environment_2/lib/python3.7/http/client.py", line 1016, in _send_output
    self.send(msg)
  File "/home/bryan/anaconda3/envs/environment_2/lib/python3.7/http/client.py", line 956, in send
    self.connect()
  File "/home/bryan/anaconda3/envs/environment_2/lib/python3.7/site-packages/urllib3/connection.py", line 181, in connect
    conn = self._new_conn()
  File "/home/bryan/anaconda3/envs/environment_2/lib/python3.7/site-packages/urllib3/connection.py", line 168, in _new_conn
    self, "Failed to establish a new connection: %s" % e)
urllib3.exceptions.NewConnectionError: <urllib3.connection.HTTPConnection object at 0x7fd214a62710>: Failed to establish a new connection: [Errno 111] Connection refused

During handling of the above exception, another exception occurred:

Traceback (most recent call last):
  File "/home/bryan/Desktop/Utilities/Python/RevPie/AutoRevPie/AutomateRevPie/AutomateRevPie.py", line 763, in checkBrowser
    browser.title
  File "/home/bryan/anaconda3/envs/environment_2/lib/python3.7/site-packages/selenium/webdriver/remote/webdriver.py", line 342, in title
    resp = self.execute(Command.GET_TITLE)
  File "/home/bryan/anaconda3/envs/environment_2/lib/python3.7/site-packages/selenium/webdriver/remote/webdriver.py", line 319, in execute
    response = self.command_executor.execute(driver_command, params)
  File "/home/bryan/anaconda3/envs/environment_2/lib/python3.7/site-packages/selenium/webdriver/remote/remote_connection.py", line 374, in execute
    return self._request(command_info[0], url, body=data)
  File "/home/bryan/anaconda3/envs/environment_2/lib/python3.7/site-packages/selenium/webdriver/remote/remote_connection.py", line 397, in _request
    resp = self._conn.request(method, url, body=body, headers=headers)
  File "/home/bryan/anaconda3/envs/environment_2/lib/python3.7/site-packages/urllib3/request.py", line 68, in request
    **urlopen_kw)
  File "/home/bryan/anaconda3/envs/environment_2/lib/python3.7/site-packages/urllib3/request.py", line 89, in request_encode_url
    return self.urlopen(method, url, **extra_kw)
  File "/home/bryan/anaconda3/envs/environment_2/lib/python3.7/site-packages/urllib3/poolmanager.py", line 324, in urlopen
    response = conn.urlopen(method, u.request_uri, **kw)
  File "/home/bryan/anaconda3/envs/environment_2/lib/python3.7/site-packages/urllib3/connectionpool.py", line 667, in urlopen
    **response_kw)
  File "/home/bryan/anaconda3/envs/environment_2/lib/python3.7/site-packages/urllib3/connectionpool.py", line 667, in urlopen
    **response_kw)
  File "/home/bryan/anaconda3/envs/environment_2/lib/python3.7/site-packages/urllib3/connectionpool.py", line 667, in urlopen
    **response_kw)
  File "/home/bryan/anaconda3/envs/environment_2/lib/python3.7/site-packages/urllib3/connectionpool.py", line 638, in urlopen
    _stacktrace=sys.exc_info()[2])
  File "/home/bryan/anaconda3/envs/environment_2/lib/python3.7/site-packages/urllib3/util/retry.py", line 399, in increment
    raise MaxRetryError(_pool, url, error or ResponseError(cause))
urllib3.exceptions.MaxRetryError: HTTPConnectionPool(host='127.0.0.1', port=49779): Max retries exceeded with url: /session/be5dd6cf-ad76-4fc8-b5a9-09176771fe7b/title (Caused by NewConnectionError('<urllib3.connection.HTTPConnection object at 0x7fd214a62710>: Failed to establish a new connection: [Errno 111] Connection refused'))

2019-06-06 11:01:27.904943 
-------------------- 


switchTabs: Error while switching tabs, closing...

HTTPConnectionPool(host='127.0.0.1', port=49779): Max retries exceeded with url: /session/be5dd6cf-ad76-4fc8-b5a9-09176771fe7b/window/handles (Caused by NewConnectionError('<urllib3.connection.HTTPConnection object at 0x7fd214ab3a90>: Failed to establish a new connection: [Errno 111] Connection refused'))
Traceback (most recent call last):
  File "/home/bryan/anaconda3/envs/environment_2/lib/python3.7/site-packages/urllib3/connection.py", line 159, in _new_conn
    (self._dns_host, self.port), self.timeout, **extra_kw)
  File "/home/bryan/anaconda3/envs/environment_2/lib/python3.7/site-packages/urllib3/util/connection.py", line 80, in create_connection
    raise err
  File "/home/bryan/anaconda3/envs/environment_2/lib/python3.7/site-packages/urllib3/util/connection.py", line 70, in create_connection
    sock.connect(sa)
ConnectionRefusedError: [Errno 111] Connection refused

During handling of the above exception, another exception occurred:

Traceback (most recent call last):
  File "/home/bryan/anaconda3/envs/environment_2/lib/python3.7/site-packages/urllib3/connectionpool.py", line 600, in urlopen
    chunked=chunked)
  File "/home/bryan/anaconda3/envs/environment_2/lib/python3.7/site-packages/urllib3/connectionpool.py", line 354, in _make_request
    conn.request(method, url, **httplib_request_kw)
  File "/home/bryan/anaconda3/envs/environment_2/lib/python3.7/http/client.py", line 1229, in request
    self._send_request(method, url, body, headers, encode_chunked)
  File "/home/bryan/anaconda3/envs/environment_2/lib/python3.7/http/client.py", line 1275, in _send_request
    self.endheaders(body, encode_chunked=encode_chunked)
  File "/home/bryan/anaconda3/envs/environment_2/lib/python3.7/http/client.py", line 1224, in endheaders
    self._send_output(message_body, encode_chunked=encode_chunked)
  File "/home/bryan/anaconda3/envs/environment_2/lib/python3.7/http/client.py", line 1016, in _send_output
    self.send(msg)
  File "/home/bryan/anaconda3/envs/environment_2/lib/python3.7/http/client.py", line 956, in send
    self.connect()
  File "/home/bryan/anaconda3/envs/environment_2/lib/python3.7/site-packages/urllib3/connection.py", line 181, in connect
    conn = self._new_conn()
  File "/home/bryan/anaconda3/envs/environment_2/lib/python3.7/site-packages/urllib3/connection.py", line 168, in _new_conn
    self, "Failed to establish a new connection: %s" % e)
urllib3.exceptions.NewConnectionError: <urllib3.connection.HTTPConnection object at 0x7fd214ab3a90>: Failed to establish a new connection: [Errno 111] Connection refused

During handling of the above exception, another exception occurred:

Traceback (most recent call last):
  File "/home/bryan/Desktop/Utilities/Python/RevPie/AutoRevPie/AutomateRevPie/AutomateRevPie.py", line 749, in switchToTab
    browser.switch_to.window(browser.window_handles[tab])
  File "/home/bryan/anaconda3/envs/environment_2/lib/python3.7/site-packages/selenium/webdriver/remote/webdriver.py", line 724, in window_handles
    return self.execute(Command.W3C_GET_WINDOW_HANDLES)['value']
  File "/home/bryan/anaconda3/envs/environment_2/lib/python3.7/site-packages/selenium/webdriver/remote/webdriver.py", line 319, in execute
    response = self.command_executor.execute(driver_command, params)
  File "/home/bryan/anaconda3/envs/environment_2/lib/python3.7/site-packages/selenium/webdriver/remote/remote_connection.py", line 374, in execute
    return self._request(command_info[0], url, body=data)
  File "/home/bryan/anaconda3/envs/environment_2/lib/python3.7/site-packages/selenium/webdriver/remote/remote_connection.py", line 397, in _request
    resp = self._conn.request(method, url, body=body, headers=headers)
  File "/home/bryan/anaconda3/envs/environment_2/lib/python3.7/site-packages/urllib3/request.py", line 68, in request
    **urlopen_kw)
  File "/home/bryan/anaconda3/envs/environment_2/lib/python3.7/site-packages/urllib3/request.py", line 89, in request_encode_url
    return self.urlopen(method, url, **extra_kw)
  File "/home/bryan/anaconda3/envs/environment_2/lib/python3.7/site-packages/urllib3/poolmanager.py", line 324, in urlopen
    response = conn.urlopen(method, u.request_uri, **kw)
  File "/home/bryan/anaconda3/envs/environment_2/lib/python3.7/site-packages/urllib3/connectionpool.py", line 667, in urlopen
    **response_kw)
  File "/home/bryan/anaconda3/envs/environment_2/lib/python3.7/site-packages/urllib3/connectionpool.py", line 667, in urlopen
    **response_kw)
  File "/home/bryan/anaconda3/envs/environment_2/lib/python3.7/site-packages/urllib3/connectionpool.py", line 667, in urlopen
    **response_kw)
  File "/home/bryan/anaconda3/envs/environment_2/lib/python3.7/site-packages/urllib3/connectionpool.py", line 638, in urlopen
    _stacktrace=sys.exc_info()[2])
  File "/home/bryan/anaconda3/envs/environment_2/lib/python3.7/site-packages/urllib3/util/retry.py", line 399, in increment
    raise MaxRetryError(_pool, url, error or ResponseError(cause))
urllib3.exceptions.MaxRetryError: HTTPConnectionPool(host='127.0.0.1', port=49779): Max retries exceeded with url: /session/be5dd6cf-ad76-4fc8-b5a9-09176771fe7b/window/handles (Caused by NewConnectionError('<urllib3.connection.HTTPConnection object at 0x7fd214ab3a90>: Failed to establish a new connection: [Errno 111] Connection refused'))

2019-06-06 11:01:30.909565 
-------------------- 

Error: error while executing AutoRevPie, closing...

HTTPConnectionPool(host='127.0.0.1', port=49779): Max retries exceeded with url: /session/be5dd6cf-ad76-4fc8-b5a9-09176771fe7b/execute/sync (Caused by NewConnectionError('<urllib3.connection.HTTPConnection object at 0x7fd214a8f630>: Failed to establish a new connection: [Errno 111] Connection refused'))
Traceback (most recent call last):
  File "/home/bryan/anaconda3/envs/environment_2/lib/python3.7/site-packages/urllib3/connection.py", line 159, in _new_conn
    (self._dns_host, self.port), self.timeout, **extra_kw)
  File "/home/bryan/anaconda3/envs/environment_2/lib/python3.7/site-packages/urllib3/util/connection.py", line 80, in create_connection
    raise err
  File "/home/bryan/anaconda3/envs/environment_2/lib/python3.7/site-packages/urllib3/util/connection.py", line 70, in create_connection
    sock.connect(sa)
ConnectionRefusedError: [Errno 111] Connection refused

During handling of the above exception, another exception occurred:

Traceback (most recent call last):
  File "/home/bryan/anaconda3/envs/environment_2/lib/python3.7/site-packages/urllib3/connectionpool.py", line 600, in urlopen
    chunked=chunked)
  File "/home/bryan/anaconda3/envs/environment_2/lib/python3.7/site-packages/urllib3/connectionpool.py", line 354, in _make_request
    conn.request(method, url, **httplib_request_kw)
  File "/home/bryan/anaconda3/envs/environment_2/lib/python3.7/http/client.py", line 1229, in request
    self._send_request(method, url, body, headers, encode_chunked)
  File "/home/bryan/anaconda3/envs/environment_2/lib/python3.7/http/client.py", line 1275, in _send_request
    self.endheaders(body, encode_chunked=encode_chunked)
  File "/home/bryan/anaconda3/envs/environment_2/lib/python3.7/http/client.py", line 1224, in endheaders
    self._send_output(message_body, encode_chunked=encode_chunked)
  File "/home/bryan/anaconda3/envs/environment_2/lib/python3.7/http/client.py", line 1016, in _send_output
    self.send(msg)
  File "/home/bryan/anaconda3/envs/environment_2/lib/python3.7/http/client.py", line 956, in send
    self.connect()
  File "/home/bryan/anaconda3/envs/environment_2/lib/python3.7/site-packages/urllib3/connection.py", line 181, in connect
    conn = self._new_conn()
  File "/home/bryan/anaconda3/envs/environment_2/lib/python3.7/site-packages/urllib3/connection.py", line 168, in _new_conn
    self, "Failed to establish a new connection: %s" % e)
urllib3.exceptions.NewConnectionError: <urllib3.connection.HTTPConnection object at 0x7fd214a8f630>: Failed to establish a new connection: [Errno 111] Connection refused

During handling of the above exception, another exception occurred:

Traceback (most recent call last):
  File "AutoRevPie.py", line 117, in <module>
    AutoRP_obj.autoRevPie(RepCounter.repCount)
  File "/home/bryan/Desktop/Utilities/Python/RevPie/AutoRevPie/AutomateRevPie/AutomateRevPie.py", line 335, in autoRevPie
    , self.campaigns[self.currentCampaign+1][0])
  File "/home/bryan/Desktop/Utilities/Python/RevPie/AutoRevPie/AutomateRevPie/AutomateRevPie.py", line 157, in switchCampaigns
    + campaignID_1 + ", '" + campaignName_1 + "')")
  File "/home/bryan/anaconda3/envs/environment_2/lib/python3.7/site-packages/selenium/webdriver/remote/webdriver.py", line 636, in execute_script
    'args': converted_args})['value']
  File "/home/bryan/anaconda3/envs/environment_2/lib/python3.7/site-packages/selenium/webdriver/remote/webdriver.py", line 319, in execute
    response = self.command_executor.execute(driver_command, params)
  File "/home/bryan/anaconda3/envs/environment_2/lib/python3.7/site-packages/selenium/webdriver/remote/remote_connection.py", line 374, in execute
    return self._request(command_info[0], url, body=data)
  File "/home/bryan/anaconda3/envs/environment_2/lib/python3.7/site-packages/selenium/webdriver/remote/remote_connection.py", line 397, in _request
    resp = self._conn.request(method, url, body=body, headers=headers)
  File "/home/bryan/anaconda3/envs/environment_2/lib/python3.7/site-packages/urllib3/request.py", line 72, in request
    **urlopen_kw)
  File "/home/bryan/anaconda3/envs/environment_2/lib/python3.7/site-packages/urllib3/request.py", line 150, in request_encode_body
    return self.urlopen(method, url, **extra_kw)
  File "/home/bryan/anaconda3/envs/environment_2/lib/python3.7/site-packages/urllib3/poolmanager.py", line 324, in urlopen
    response = conn.urlopen(method, u.request_uri, **kw)
  File "/home/bryan/anaconda3/envs/environment_2/lib/python3.7/site-packages/urllib3/connectionpool.py", line 667, in urlopen
    **response_kw)
  File "/home/bryan/anaconda3/envs/environment_2/lib/python3.7/site-packages/urllib3/connectionpool.py", line 667, in urlopen
    **response_kw)
  File "/home/bryan/anaconda3/envs/environment_2/lib/python3.7/site-packages/urllib3/connectionpool.py", line 667, in urlopen
    **response_kw)
  File "/home/bryan/anaconda3/envs/environment_2/lib/python3.7/site-packages/urllib3/connectionpool.py", line 638, in urlopen
    _stacktrace=sys.exc_info()[2])
  File "/home/bryan/anaconda3/envs/environment_2/lib/python3.7/site-packages/urllib3/util/retry.py", line 399, in increment
    raise MaxRetryError(_pool, url, error or ResponseError(cause))
urllib3.exceptions.MaxRetryError: HTTPConnectionPool(host='127.0.0.1', port=49779): Max retries exceeded with url: /session/be5dd6cf-ad76-4fc8-b5a9-09176771fe7b/execute/sync (Caused by NewConnectionError('<urllib3.connection.HTTPConnection object at 0x7fd214a8f630>: Failed to establish a new connection: [Errno 111] Connection refused'))

